Workbook
Name UPDATE: 'Raw Data'!$E$1

Sheet Profit & Loss
A1: ='Raw Data'!B1 -> TATA STEEL LTD | H1: =UPDATE | M1: SCREENER.IN
A3: Narration | B3: ='Raw Data'!B16 -> 42825 | C3: ='Raw Data'!C16 -> 43190 | D3: ='Raw Data'!D16 -> 43555 | E3: ='Raw Data'!E16 -> 43921 | F3: ='Raw Data'!F16 -> 44286 | G3: ='Raw Data'!G16 -> 44651 | H3: ='Raw Data'!H16 -> 45016 | I3: ='Raw Data'!I16 -> 45382 | ... K3: ='Raw Data'!K16 -> 46112 | L3: Trailing | M3: Best Case | N3: Worst Case
A4: Sales | B4: ='Raw Data'!B17 -> 112299.42 | C4: ='Raw Data'!C17 -> 123249.07 | D4: ='Raw Data'!D17 -> 157668.99 | E4: ='Raw Data'!E17 -> 139816.65 | F4: ='Raw Data'!F17 -> 156477.4 | G4: ='Raw Data'!G17 -> 243959.17 | H4: ='Raw Data'!H17 -> 243352.69 | I4: ='Raw Data'!I17 -> 229170.78 | ... K4: ='Raw Data'!K17 -> 232139.94 | L4: =SUM(Quarters!H4:K4) -> 239756.11 | M4: =$K4+M23*K4 -> 246583.38 | N4: =$K4+N23*L4 -> 228399.55
A5: Expenses | B5: =SUM('Raw Data'!B18,'Raw Data'!B20:B24, -1*'Raw Data'!B19) -> 99155.79 | C5: =SUM('Raw Data'!C18,'Raw Data'!C20:C24, -1*'Raw Data'!C19) -> 101815.88 | D5: =SUM('Raw Data'!D18,'Raw Data'!D20:D24, -1*'Raw Data'!D19) -> 128350.77 | E5: =SUM('Raw Data'!E18,'Raw Data'!E20:E24, -1*'Raw Data'!E19) -> 122353.59 | F5: =SUM('Raw Data'!F18,'Raw Data'!F20:F24, -1*'Raw Data'!F19) -> 125973.14 | G5: =SUM('Raw Data'!G18,'Raw Data'!G20:G24, -1*'Raw Data'!G19) -> 180469.22 | H5: =SUM('Raw Data'!H18,'Raw Data'!H20:H24, -1*'Raw Data'!H19) -> 211052.53 | I5: =SUM('Raw Data'!I18,'Raw Data'!I20:I24, -1*'Raw Data'!I19) -> 206922.86 | ... K5: =SUM('Raw Data'!K18,'Raw Data'!K20:K24, -1*'Raw Data'!K19) -> 197787.5 | L5: =SUM(Quarters!H5:K5) -> 203566.87 | M5: =M4-M6 -> 209363.62 | N5: =N4-N6 -> 200885.3
A6: Operating Profit | B6: =B4-B5 -> 13143.63 | C6: =C4-C5 -> 21433.19 | D6: =D4-D5 -> 29318.22 | E6: =E4-E5 -> 17463.06 | F6: =F4-F5 -> 30504.26 | G6: =G4-G5 -> 63489.95 | H6: =H4-H5 -> 32300.16 | I6: =I4-I5 -> 22247.92 | ... K6: =K4-K5 -> 34352.44 | L6: =SUM(Quarters!H6:K6) -> 36189.24 | M6: =M4*M24 -> 37219.762 | N6: =N4*N24 -> 27514.249
A7: Other Income | B7: ='Raw Data'!B25 -> -3789.11 | C7: ='Raw Data'!C25 -> 10898.41 | D7: ='Raw Data'!D25 -> 1524.31 | E7: ='Raw Data'!E25 -> -2883.63 | F7: ='Raw Data'!F25 -> 179.78 | G7: ='Raw Data'!G25 -> 1299.99 | H7: ='Raw Data'!H25 -> 1568.86 | I7: ='Raw Data'!I25 -> -6005.23 | ... K7: ='Raw Data'!K25 -> 737.82 | L7: =SUM(Quarters!H7:K7) -> 484.9 | M7: 0 | N7: 0
A8: Depreciation | B8: ='Raw Data'!B26 -> 5672.88 | C8: ='Raw Data'!C26 -> 5741.7 | D8: ='Raw Data'!D26 -> 7341.83 | E8: ='Raw Data'!E26 -> 8440.73 | F8: ='Raw Data'!F26 -> 9233.64 | G8: ='Raw Data'!G26 -> 9100.87 | H8: ='Raw Data'!H26 -> 9335.2 | I8: ='Raw Data'!I26 -> 9882.16 | ... K8: ='Raw Data'!K26 -> 11954.51 | L8: =SUM(Quarters!H8:K8) -> 12849.86 | M8: =+$L8 -> 12849.86 | N8: =+$L8 -> 12849.86
A9: Interest | B9: ='Raw Data'!B27 -> 5072.2 | C9: ='Raw Data'!C27 -> 5454.74 | D9: ='Raw Data'!D27 -> 7660.1 | E9: ='Raw Data'!E27 -> 7533.46 | F9: ='Raw Data'!F27 -> 7606.71 | G9: ='Raw Data'!G27 -> 5462.2 | H9: ='Raw Data'!H27 -> 6298.7 | I9: ='Raw Data'!I27 -> 7507.57 | ... K9: ='Raw Data'!K27 -> 7167.06 | L9: =SUM(Quarters!H9:K9) -> 7085.14 | M9: =+$L9 -> 7085.14 | N9: =+$L9 -> 7085.14
A10: Profit before tax | B10: ='Raw Data'!B28 -> -1390.56 | C10: ='Raw Data'!C28 -> 21135.16 | D10: ='Raw Data'!D28 -> 15840.6 | E10: ='Raw Data'!E28 -> -1394.76 | F10: ='Raw Data'!F28 -> 13843.69 | G10: ='Raw Data'!G28 -> 50226.87 | H10: ='Raw Data'!H28 -> 18235.12 | I10: ='Raw Data'!I28 -> -1147.04 | ... K10: ='Raw Data'!K28 -> 15968.69 | L10: =SUM(Quarters!H10:K10) -> 16739.14 | M10: =M6+M7-SUM(M8:M9) -> 17284.762 | N10: =N6+N7-SUM(N8:N9) -> 7579.2489
A11: Tax | B11: ='Raw Data'!B29 -> 2778.01 | C11: ='Raw Data'!C29 -> 3392.33 | D11: ='Raw Data'!D29 -> 6718.43 | E11: ='Raw Data'!E29 -> -2568.41 | F11: ='Raw Data'!F29 -> 5653.9 | G11: ='Raw Data'!G29 -> 8477.55 | H11: ='Raw Data'!H29 -> 10159.77 | I11: ='Raw Data'!I29 -> 3762.57 | ... K11: ='Raw Data'!K29 -> 5082.87 | L11: =SUM(Quarters!H11:K11) -> 5475.44 | M11: =IF($L10>0,$L11/$L10,0) -> 0.32710402 | N11: =IF($L10>0,$L11/$L10,0) -> 0.32710402
A12: Net profit | B12: ='Raw Data'!B30 -> -4240.8 | C12: ='Raw Data'!C30 -> 13434.33 | D12: ='Raw Data'!D30 -> 10218.33 | E12: ='Raw Data'!E30 -> 1556.54 | F12: ='Raw Data'!F30 -> 7490.22 | G12: ='Raw Data'!G30 -> 40153.93 | H12: ='Raw Data'!H30 -> 8760.4 | I12: ='Raw Data'!I30 -> -4437.44 | ... K12: ='Raw Data'!K30 -> 10793.87 | L12: =SUM(Quarters!H12:K12) -> 11034.54 | M12: =M10-M11*M10 -> 11630.847 | N12: =N10-N11*N10 -> 5100.0461
A13: EPS | B13: =IF('Raw Data'!B93>0,B12/'Raw Data'!B93,0) -> -3.7641796 | C13: =IF('Raw Data'!C93>0,C12/'Raw Data'!C93,0) -> 11.925937 | D13: =IF('Raw Data'!D93>0,D12/'Raw Data'!D93,0) -> 9.070946 | E13: =IF('Raw Data'!E93>0,E12/'Raw Data'!E93,0) -> 1.381761 | F13: =IF('Raw Data'!F93>0,F12/'Raw Data'!F93,0) -> 6.2596378 | G13: =IF('Raw Data'!G93>0,G12/'Raw Data'!G93,0) -> 32.878023 | H13: =IF('Raw Data'!H93>0,H12/'Raw Data'!H93,0) -> 7.1680236 | I13: =IF('Raw Data'!I93>0,I12/'Raw Data'!I93,0) -> -3.5546441 | ... K13: =IF('Raw Data'!K93>0,K12/'Raw Data'!K93,0) -> 8.6465094 | L13: =IF('Raw Data'!$B6>0,'Profit & Loss'!L12/'Raw Data'!$B6,0) -> 8.8423598 | M13: =IF('Raw Data'!$B6>0,'Profit & Loss'!M12/'Raw Data'!$B6,0) -> 9.320201 | N13: =IF('Raw Data'!$B6>0,'Profit & Loss'!N12/'Raw Data'!$B6,0) -> 4.0868439
A14: Price to earning | B14: =IF(B15>0,B15/B13,"") -> -12.217802 | C14: =IF(C15>0,C15/C13,"") -> 4.7887221 | D14: =IF(D15>0,D15/D13,"") -> 5.7436126 | E14: =IF(E15>0,E15/E13,"") -> 19.511333 | F14: =IF(F15>0,F15/F13,"") -> 12.970399 | G14: =IF(G15>0,G15/G13,"") -> 3.9759081 | H14: =IF(H15>0,H15/H13,"") -> 14.578635 | I14: =IF(I15>0,I15/I13,"") -> -43.844051 | ... K14: =IF(K15>0,K15/K13,"") -> 22.189301 | L14: =IF(L13>0,L15/L13,0) -> 19.791097 | M14: =M25 -> 32.757286 | N14: =N25 -> 17.760052
A15: Price | B15: ='Raw Data'!B90 -> 45.99 | C15: ='Raw Data'!C90 -> 57.11 | D15: ='Raw Data'!D90 -> 52.1 | E15: ='Raw Data'!E90 -> 26.96 | F15: ='Raw Data'!F90 -> 81.19 | G15: ='Raw Data'!G90 -> 130.72 | H15: ='Raw Data'!H90 -> 104.5 | I15: ='Raw Data'!I90 -> 155.85 | ... K15: ='Raw Data'!K90 -> 191.86 | L15: ='Raw Data'!B8 -> 175 | M15: =M13*M14 -> 305.30449 | N15: =N13*N14 -> 72.582561
A17: RATIOS:
A18: Dividend Payout | B18: =IF('Raw Data'!B30>0, 'Raw Data'!B31/'Raw Data'!B30, 0) -> 0 | C18: =IF('Raw Data'!C30>0, 'Raw Data'!C31/'Raw Data'!C30, 0) -> 0.085225687 | D18: =IF('Raw Data'!D30>0, 'Raw Data'!D31/'Raw Data'!D30, 0) -> 0.14566177 | E18: =IF('Raw Data'!E30>0, 'Raw Data'!E31/'Raw Data'!E30, 0) -> 0.73557377 | F18: =IF('Raw Data'!F30>0, 'Raw Data'!F31/'Raw Data'!F30, 0) -> 0.39972391 | G18: =IF('Raw Data'!G30>0, 'Raw Data'!G31/'Raw Data'!G30, 0) -> 0.15510736 | H18: =IF('Raw Data'!H30>0, 'Raw Data'!H31/'Raw Data'!H30, 0) -> 0.50185608 | I18: =IF('Raw Data'!I30>0, 'Raw Data'!I31/'Raw Data'!I30, 0) -> 0 | ... K18: =IF('Raw Data'!K30>0, 'Raw Data'!K31/'Raw Data'!K30, 0) -> 0.4622772
A19: OPM | B19: =IF(B6>0,B6/B4,0) -> 0.11704094 | C19: =IF(C6>0,C6/C4,0) -> 0.17390143 | D19: =IF(D6>0,D6/D4,0) -> 0.18594792 | E19: =IF(E6>0,E6/E4,0) -> 0.12489972 | F19: =IF(F6>0,F6/F4,0) -> 0.19494355 | G19: =IF(G6>0,G6/G4,0) -> 0.26024826 | H19: =IF(H6>0,H6/H4,0) -> 0.13272983 | I19: =IF(I6>0,I6/I4,0) -> 0.09708009 | ... L19: =IF(L6>0,L6/L4,0) -> 0.15094189
G22: TRENDS: | H22: 10 YEARS | I22: 7 YEARS | J22: 5 YEARS | K22: 3 YEARS | L22: RECENT | M22: BEST | N22: WORST
G23: Sales Growth | H23: =IF(B4=0,"",POWER($K4/B4,1/9)-1) -> 0.084030178 | I23: =IF(D4=0,"",POWER($K4/D4,1/7)-1) -> 0.056818755 | J23: =IF(F4=0,"",POWER($K4/F4,1/5)-1) -> 0.082080696 | K23: =IF(H4=0,"",POWER($K4/H4, 1/3)-1) -> -0.01560083 | L23: =IF(ISERROR(MAX(IF(J4=0,"",(K4-J4)/J4),IF(K4=0,"",(L4-K4)/K4))),"",MAX(IF(J4=0,"",(K4-J4)/J4),IF(K4=0,"",(L4-K4)/K4))) -> 0.062218696 | M23: =MAX(K23:L23) -> 0.062218696 | N23: =MIN(H23:L23) -> -0.01560083
G24: OPM | H24: =IF(SUM(B4:$K$4)=0,"",SUMPRODUCT(B19:$K$19,B4:$K$4)/SUM(B4:$K$4)) -> 0.15595138 | I24: =IF(SUM(E4:$K$4)=0,"",SUMPRODUCT(E19:$K$19,E4:$K$4)/SUM(E4:$K$4)) -> 0.15419374 | J24: =IF(SUM(G4:$K$4)=0,"",SUMPRODUCT(G19:$K$19,G4:$K$4)/SUM(G4:$K$4)) -> 0.15223975 | K24: =IF(SUM(I4:$K$4)=0, "", SUMPRODUCT(I19:$K$19,I4:$K$4)/SUM(I4:$K$4)) -> 0.12046543 | L24: =L19 -> 0.15094189 | M24: =MAX(K24:L24) -> 0.15094189 | N24: =MIN(H24:L24) -> 0.12046543
G25: Price to Earning | H25: =IF(ISERROR(AVERAGEIF(B14:$L14,">0")),"",AVERAGEIF(B14:$L14,">0")) -> 17.760052 | I25: =IF(ISERROR(AVERAGEIF(E14:$L14,">0")),"",AVERAGEIF(E14:$L14,">0")) -> 21.329733 | J25: =IF(ISERROR(AVERAGEIF(G14:$L14,">0")),"",AVERAGEIF(G14:$L14,">0")) -> 23.36528 | K25: =IF(ISERROR(AVERAGEIF(I14:$L14,">0")),"",AVERAGEIF(I14:$L14,">0")) -> 32.757286 | L25: =L14 -> 19.791097 | M25: =MAX(K25:L25) -> 32.757286 | N25: =MIN(H25:L25) -> 17.760052

Sheet Quarters
A1: ='Profit & Loss'!A1 -> TATA STEEL LTD | E1: =UPDATE | J1: SCREENER.IN
A3: Narration | B3: ='Raw Data'!B41 -> 45382 | C3: ='Raw Data'!C41 -> 45473 | D3: ='Raw Data'!D41 -> 45565 | E3: ='Raw Data'!E41 -> 45657 | F3: ='Raw Data'!F41 -> 45747 | G3: ='Raw Data'!G41 -> 45838 | H3: ='Raw Data'!H41 -> 45930 | I3: ='Raw Data'!I41 -> 46022 | ... K3: ='Raw Data'!K41 -> 46203
A4: Sales | B4: ='Raw Data'!B42 -> 58687.31 | C4: ='Raw Data'!C42 -> 54771.39 | D4: ='Raw Data'!D42 -> 53904.71 | E4: ='Raw Data'!E42 -> 53648.3 | F4: ='Raw Data'!F42 -> 56218.11 | G4: ='Raw Data'!G42 -> 53178.12 | H4: ='Raw Data'!H42 -> 58689.29 | I4: ='Raw Data'!I42 -> 57002.4 | ... K4: ='Raw Data'!K42 -> 60794.29
A5: Expenses | B5: ='Raw Data'!B43 -> 52086.68 | C5: ='Raw Data'!C43 -> 48076.92 | D5: ='Raw Data'!D43 -> 47788.92 | E5: ='Raw Data'!E43 -> 47744.81 | F5: ='Raw Data'!F43 -> 49658.89 | G5: ='Raw Data'!G43 -> 45750.58 | H5: ='Raw Data'!H43 -> 49792.75 | I5: ='Raw Data'!I43 -> 48802.7 | ... K5: ='Raw Data'!K43 -> 51529.95
A6: Operating Profit | B6: ='Raw Data'!B50 -> 6600.63 | C6: ='Raw Data'!C50 -> 6694.47 | D6: ='Raw Data'!D50 -> 6115.79 | E6: ='Raw Data'!E50 -> 5903.49 | F6: ='Raw Data'!F50 -> 6559.22 | G6: ='Raw Data'!G50 -> 7427.54 | H6: ='Raw Data'!H50 -> 8896.54 | I6: ='Raw Data'!I50 -> 8199.7 | ... K6: ='Raw Data'!K50 -> 9264.34
A7: Other Income | B7: ='Raw Data'!B44 -> -381.56 | C7: ='Raw Data'!C44 -> -5.51 | D7: ='Raw Data'!D44 -> 616.68 | E7: ='Raw Data'!E44 -> 141.82 | F7: ='Raw Data'!F44 -> 149.19 | G7: ='Raw Data'!G44 -> 236.27 | H7: ='Raw Data'!H44 -> -6.11 | I7: ='Raw Data'!I44 -> 465.17 | ... K7: ='Raw Data'!K44 -> -16.65
A8: Depreciation | B8: ='Raw Data'!B45 -> 2567.95 | C8: ='Raw Data'!C45 -> 2535.43 | D8: ='Raw Data'!D45 -> 2596.74 | E8: ='Raw Data'!E45 -> 2569.19 | F8: ='Raw Data'!F45 -> 2719.97 | G8: ='Raw Data'!G45 -> 2744.3 | H8: ='Raw Data'!H45 -> 2893 | I8: ='Raw Data'!I45 -> 3048.81 | ... K8: ='Raw Data'!K45 -> 3639.65
A9: Interest | B9: ='Raw Data'!B46 -> 1842.25 | C9: ='Raw Data'!C46 -> 1776.71 | D9: ='Raw Data'!D46 -> 1971.4 | E9: ='Raw Data'!E46 -> 1804.09 | F9: ='Raw Data'!F46 -> 1788.75 | G9: ='Raw Data'!G46 -> 1852.43 | H9: ='Raw Data'!H46 -> 1774.96 | I9: ='Raw Data'!I46 -> 1747.29 | ... K9: ='Raw Data'!K46 -> 1770.51
A10: Profit before tax | B10: ='Raw Data'!B47 -> 1808.87 | C10: ='Raw Data'!C47 -> 2376.82 | D10: ='Raw Data'!D47 -> 2164.33 | E10: ='Raw Data'!E47 -> 1672.03 | F10: ='Raw Data'!F47 -> 2199.69 | G10: ='Raw Data'!G47 -> 3067.08 | H10: ='Raw Data'!H47 -> 4222.47 | I10: ='Raw Data'!I47 -> 3868.77 | ... K10: ='Raw Data'!K47 -> 3837.53
A11: Tax | B11: ='Raw Data'!B48 -> 1254.31 | C11: ='Raw Data'!C48 -> 1458.25 | D11: ='Raw Data'!D48 -> 1405.49 | E11: ='Raw Data'!E48 -> 1376.54 | F11: ='Raw Data'!F48 -> 998.81 | G11: ='Raw Data'!G48 -> 1059.72 | H11: ='Raw Data'!H48 -> 1039.38 | I11: ='Raw Data'!I48 -> 1138.4 | ... K11: ='Raw Data'!K48 -> 1452.29
A12: Net profit | B12: ='Raw Data'!B49 -> 611.48 | C12: ='Raw Data'!C49 -> 959.61 | D12: ='Raw Data'!D49 -> 833.45 | E12: ='Raw Data'!E49 -> 326.64 | F12: ='Raw Data'!F49 -> 1300.81 | G12: ='Raw Data'!G49 -> 2077.68 | H12: ='Raw Data'!H49 -> 3101.75 | I12: ='Raw Data'!I49 -> 2688.7 | ... K12: ='Raw Data'!K49 -> 2318.35
A14: OPM | B14: =IF(B4>0,B6/B4,"") -> 0.11247116 | C14: =IF(C4>0,C6/C4,"") -> 0.12222567 | D14: =IF(D4>0,D6/D4,"") -> 0.11345558 | E14: =IF(E4>0,E6/E4,"") -> 0.11004058 | F14: =IF(F4>0,F6/F4,"") -> 0.1166745 | G14: =IF(G4>0,G6/G4,"") -> 0.13967286 | H14: =IF(H4>0,H6/H4,"") -> 0.15158711 | I14: =IF(I4>0,I6/I4,"") -> 0.14384833 | ... K14: =IF(K4>0,K6/K4,"") -> 0.15238832

Sheet Balance Sheet
A1: ='Profit & Loss'!A1 -> TATA STEEL LTD | E1: =UPDATE | J1: SCREENER.IN
A3: Narration | B3: ='Raw Data'!B56 -> 42825 | C3: ='Raw Data'!C56 -> 43190 | D3: ='Raw Data'!D56 -> 43555 | E3: ='Raw Data'!E56 -> 43921 | F3: ='Raw Data'!F56 -> 44286 | G3: ='Raw Data'!G56 -> 44651 | H3: ='Raw Data'!H56 -> 45016 | I3: ='Raw Data'!I56 -> 45382 | ... K3: ='Raw Data'!K56 -> 46112
A4: Equity Share Capital | B4: ='Raw Data'!B57 -> 970.24 | C4: ='Raw Data'!C57 -> 1144.95 | D4: ='Raw Data'!D57 -> 1144.94 | E4: ='Raw Data'!E57 -> 1144.95 | F4: ='Raw Data'!F57 -> 1197.61 | G4: ='Raw Data'!G57 -> 1221.21 | H4: ='Raw Data'!H57 -> 1221.24 | I4: ='Raw Data'!I57 -> 1247.44 | ... K4: ='Raw Data'!K57 -> 1247.44
A5: Reserves | B5: ='Raw Data'!B58 -> 36849.08 | C5: ='Raw Data'!C58 -> 59725.67 | D5: ='Raw Data'!D58 -> 67780.14 | E5: ='Raw Data'!E58 -> 72431.35 | F5: ='Raw Data'!F58 -> 73041.16 | G5: ='Raw Data'!G58 -> 113221.83 | H5: ='Raw Data'!H58 -> 101860.86 | I5: ='Raw Data'!I58 -> 90788.32 | ... K5: ='Raw Data'!K58 -> 100920.21
A6: Borrowings | B6: ='Raw Data'!B59 -> 83014.49 | C6: ='Raw Data'!C59 -> 92147.05 | D6: ='Raw Data'!D59 -> 100816.22 | E6: ='Raw Data'!E59 -> 116328.2 | F6: ='Raw Data'!F59 -> 88501.41 | G6: ='Raw Data'!G59 -> 75561.35 | H6: ='Raw Data'!H59 -> 84893.05 | I6: ='Raw Data'!I59 -> 87082.12 | ... K6: ='Raw Data'!K59 -> 92381.68
A7: Other Liabilities | B7: ='Raw Data'!B60 -> 51613.56 | C7: ='Raw Data'!C60 -> 55704.47 | D7: ='Raw Data'!D60 -> 63032.14 | E7: ='Raw Data'!E60 -> 59244.62 | F7: ='Raw Data'!F60 -> 81169.01 | G7: ='Raw Data'!G60 -> 92417.28 | H7: ='Raw Data'!H60 -> 97420.63 | I7: ='Raw Data'!I60 -> 90194.54 | ... K7: ='Raw Data'!K60 -> 101965.29
A8: Total | B8: ='Raw Data'!B61 -> 172447.37 | C8: ='Raw Data'!C61 -> 208722.14 | D8: ='Raw Data'!D61 -> 232773.44 | E8: ='Raw Data'!E61 -> 249149.12 | F8: ='Raw Data'!F61 -> 243909.19 | G8: ='Raw Data'!G61 -> 282421.67 | H8: ='Raw Data'!H61 -> 285395.78 | I8: ='Raw Data'!I61 -> 269312.42 | ... K8: ='Raw Data'!K61 -> 296514.62
A10: Net Block | B10: ='Raw Data'!B62 -> 92006.55 | C10: ='Raw Data'!C62 -> 96104.89 | D10: ='Raw Data'!D62 -> 124441.91 | E10: ='Raw Data'!E62 -> 134550.66 | F10: ='Raw Data'!F62 -> 135775.18 | G10: ='Raw Data'!G62 -> 133287.83 | H10: ='Raw Data'!H62 -> 146621.46 | I10: ='Raw Data'!I62 -> 148814.38 | ... K10: ='Raw Data'!K62 -> 179908.13
A11: Capital Work in Progress | B11: ='Raw Data'!B63 -> 15784.13 | C11: ='Raw Data'!C63 -> 16614.41 | D11: ='Raw Data'!D63 -> 18641.21 | E11: ='Raw Data'!E63 -> 19496.83 | F11: ='Raw Data'!F63 -> 19007.4 | G11: ='Raw Data'!G63 -> 22045.55 | H11: ='Raw Data'!H63 -> 31213.02 | I11: ='Raw Data'!I63 -> 34355.53 | ... K11: ='Raw Data'!K63 -> 28496.71
A12: Investments | B12: ='Raw Data'!B64 -> 12457.12 | C12: ='Raw Data'!C64 -> 17899.47 | D12: ='Raw Data'!D64 -> 5738.17 | E12: ='Raw Data'!E64 -> 6285.18 | F12: ='Raw Data'!F64 -> 10681.93 | G12: ='Raw Data'!G64 -> 13139.85 | H12: ='Raw Data'!H64 -> 8410.31 | I12: ='Raw Data'!I64 -> 6257.57 | ... K12: ='Raw Data'!K64 -> 7088.85
A13: Other Assets | B13: ='Raw Data'!B65 -> 52199.57 | C13: ='Raw Data'!C65 -> 78103.37 | D13: ='Raw Data'!D65 -> 83952.15 | E13: ='Raw Data'!E65 -> 88816.45 | F13: ='Raw Data'!F65 -> 78444.68 | G13: ='Raw Data'!G65 -> 113948.44 | H13: ='Raw Data'!H65 -> 99150.99 | I13: ='Raw Data'!I65 -> 79884.94 | ... K13: ='Raw Data'!K65 -> 81020.93
A14: Total | B14: ='Raw Data'!B66 -> 172447.37 | C14: ='Raw Data'!C66 -> 208722.14 | D14: ='Raw Data'!D66 -> 232773.44 | E14: ='Raw Data'!E66 -> 249149.12 | F14: ='Raw Data'!F66 -> 243909.19 | G14: ='Raw Data'!G66 -> 282421.67 | H14: ='Raw Data'!H66 -> 285395.78 | I14: ='Raw Data'!I66 -> 269312.42 | ... K14: ='Raw Data'!K66 -> 296514.62
A16: Working Capital | B16: =B13-B7 -> 586.01 | C16: =C13-C7 -> 22398.9 | D16: =D13-D7 -> 20920.01 | E16: =E13-E7 -> 29571.83 | F16: =F13-F7 -> -2724.33 | G16: =G13-G7 -> 21531.16 | H16: =H13-H7 -> 1730.36 | I16: =I13-I7 -> -10309.6 | ... K16: =K13-K7 -> -20944.36
A17: Debtors | B17: ='Raw Data'!B67 -> 11586.82 | C17: ='Raw Data'!C67 -> 12415.52 | D17: ='Raw Data'!D67 -> 11811 | E17: ='Raw Data'!E67 -> 7884.91 | F17: ='Raw Data'!F67 -> 9539.84 | G17: ='Raw Data'!G67 -> 12246.43 | H17: ='Raw Data'!H67 -> 8257.24 | I17: ='Raw Data'!I67 -> 6263.53 | ... K17: ='Raw Data'!K67 -> 4916.89
A18: Inventory | B18: ='Raw Data'!B68 -> 24803.82 | C18: ='Raw Data'!C68 -> 28331.04 | D18: ='Raw Data'!D68 -> 31656.1 | E18: ='Raw Data'!E68 -> 31068.72 | F18: ='Raw Data'!F68 -> 33276.38 | G18: ='Raw Data'!G68 -> 48824.39 | H18: ='Raw Data'!H68 -> 54415.33 | I18: ='Raw Data'!I68 -> 49157.51 | ... K18: ='Raw Data'!K68 -> 47249.22
A20: Debtor Days | B20: =IF('Profit & Loss'!B4>0,'Balance Sheet'!B17/('Profit & Loss'!B4/365),0) -> 37.659939 | C20: =IF('Profit & Loss'!C4>0,'Balance Sheet'!C17/('Profit & Loss'!C4/365),0) -> 36.768349 | D20: =IF('Profit & Loss'!D4>0,'Balance Sheet'!D17/('Profit & Loss'!D4/365),0) -> 27.342187 | E20: =IF('Profit & Loss'!E4>0,'Balance Sheet'!E17/('Profit & Loss'!E4/365),0) -> 20.584045 | F20: =IF('Profit & Loss'!F4>0,'Balance Sheet'!F17/('Profit & Loss'!F4/365),0) -> 22.252681 | G20: =IF('Profit & Loss'!G4>0,'Balance Sheet'!G17/('Profit & Loss'!G4/365),0) -> 18.322521 | H20: =IF('Profit & Loss'!H4>0,'Balance Sheet'!H17/('Profit & Loss'!H4/365),0) -> 12.384875 | I20: =IF('Profit & Loss'!I4>0,'Balance Sheet'!I17/('Profit & Loss'!I4/365),0) -> 9.975916 | ... K20: =IF('Profit & Loss'!K4>0,'Balance Sheet'!K17/('Profit & Loss'!K4/365),0) -> 7.7309611
A21: Inventory Turnover | B21: =IF('Balance Sheet'!B18>0,'Profit & Loss'!B4/'Balance Sheet'!B18,0) -> 4.527505 | C21: =IF('Balance Sheet'!C18>0,'Profit & Loss'!C4/'Balance Sheet'!C18,0) -> 4.3503193 | D21: =IF('Balance Sheet'!D18>0,'Profit & Loss'!D4/'Balance Sheet'!D18,0) -> 4.9806827 | E21: =IF('Balance Sheet'!E18>0,'Profit & Loss'!E4/'Balance Sheet'!E18,0) -> 4.5002385 | F21: =IF('Balance Sheet'!F18>0,'Profit & Loss'!F4/'Balance Sheet'!F18,0) -> 4.7023564 | G21: =IF('Balance Sheet'!G18>0,'Profit & Loss'!G4/'Balance Sheet'!G18,0) -> 4.996666 | H21: =IF('Balance Sheet'!H18>0,'Profit & Loss'!H4/'Balance Sheet'!H18,0) -> 4.4721348 | I21: =IF('Balance Sheet'!I18>0,'Profit & Loss'!I4/'Balance Sheet'!I18,0) -> 4.6619688 | ... K21: =IF('Balance Sheet'!K18>0,'Profit & Loss'!K4/'Balance Sheet'!K18,0) -> 4.9130957
A23: Return on Equity | B23: =IF(SUM('Balance Sheet'!B4:B5)>0,'Profit & Loss'!B12/SUM('Balance Sheet'!B4:B5),"") -> -0.11213316 | C23: =IF(SUM('Balance Sheet'!C4:C5)>0,'Profit & Loss'!C12/SUM('Balance Sheet'!C4:C5),"") -> 0.22070303 | D23: =IF(SUM('Balance Sheet'!D4:D5)>0,'Profit & Loss'!D12/SUM('Balance Sheet'!D4:D5),"") -> 0.14825271 | E23: =IF(SUM('Balance Sheet'!E4:E5)>0,'Profit & Loss'!E12/SUM('Balance Sheet'!E4:E5),"") -> 0.021155454 | F23: =IF(SUM('Balance Sheet'!F4:F5)>0,'Profit & Loss'!F12/SUM('Balance Sheet'!F4:F5),"") -> 0.10089364 | G23: =IF(SUM('Balance Sheet'!G4:G5)>0,'Profit & Loss'!G12/SUM('Balance Sheet'!G4:G5),"") -> 0.35086389 | H23: =IF(SUM('Balance Sheet'!H4:H5)>0,'Profit & Loss'!H12/SUM('Balance Sheet'!H4:H5),"") -> 0.084984687 | I23: =IF(SUM('Balance Sheet'!I4:I5)>0,'Profit & Loss'!I12/SUM('Balance Sheet'!I4:I5),"") -> -0.048214303 | ... K23: =IF(SUM('Balance Sheet'!K4:K5)>0,'Profit & Loss'!K12/SUM('Balance Sheet'!K4:K5),"") -> 0.10564861
A24: Return on Capital Emp | C24: =IF((B4+B5+B6+C4+C5+C6)>0,('Profit & Loss'!C10+'Profit & Loss'!C9)*2/(B4+B5+B6+C4+C5+C6),"") -> 0.19419212 | D24: =IF((C4+C5+C6+D4+D5+D6)>0,('Profit & Loss'!D10+'Profit & Loss'!D9)*2/(C4+C5+C6+D4+D5+D6),"") -> 0.14562384 | E24: =IF((D4+D5+D6+E4+E5+E6)>0,('Profit & Loss'!E10+'Profit & Loss'!E9)*2/(D4+D5+D6+E4+E5+E6),"") -> 0.034137476 | F24: =IF((E4+E5+E6+F4+F5+F6)>0,('Profit & Loss'!F10+'Profit & Loss'!F9)*2/(E4+E5+E6+F4+F5+F6),"") -> 0.12165447 | G24: =IF((F4+F5+F6+G4+G5+G6)>0,('Profit & Loss'!G10+'Profit & Loss'!G9)*2/(F4+F5+F6+G4+G5+G6),"") -> 0.31574728 | H24: =IF((G4+G5+G6+H4+H5+H6)>0,('Profit & Loss'!H10+'Profit & Loss'!H9)*2/(G4+G5+G6+H4+H5+H6),"") -> 0.1298156 | I24: =IF((H4+H5+H6+I4+I5+I6)>0,('Profit & Loss'!I10+'Profit & Loss'!I9)*2/(H4+H5+H6+I4+I5+I6),"") -> 0.034653505 | J24: =IF((I4+I5+I6+J4+J5+J6)>0,('Profit & Loss'!J10+'Profit & Loss'!J9)*2/(I4+I5+I6+J4+J5+J6),"") -> 0.086301362 | K24: =IF((J4+J5+J6+K4+K5+K6)>0,('Profit & Loss'!K10+'Profit & Loss'!K9)*2/(J4+J5+J6+K4+K5+K6),"") -> 0.1216007

Sheet Cash Flow
A1: ='Balance Sheet'!A1 -> TATA STEEL LTD | E1: =UPDATE | J1: SCREENER.IN
A3: Narration | B3: ='Raw Data'!B81 -> 42825 | C3: ='Raw Data'!C81 -> 43190 | D3: ='Raw Data'!D81 -> 43555 | E3: ='Raw Data'!E81 -> 43921 | F3: ='Raw Data'!F81 -> 44286 | G3: ='Raw Data'!G81 -> 44651 | H3: ='Raw Data'!H81 -> 45016 | I3: ='Raw Data'!I81 -> 45382 | ... K3: ='Raw Data'!K81 -> 46112
A4: Cash from Operating Activity | B4: ='Raw Data'!B82 -> 10824.36 | C4: ='Raw Data'!C82 -> 8023.39 | D4: ='Raw Data'!D82 -> 25335.95 | E4: ='Raw Data'!E82 -> 20168.72 | F4: ='Raw Data'!F82 -> 44326.68 | G4: ='Raw Data'!G82 -> 44380.99 | H4: ='Raw Data'!H82 -> 21683.08 | I4: ='Raw Data'!I82 -> 20300.67 | ... K4: ='Raw Data'!K82 -> 35064.46
A5: Cash from Investing Activity | B5: ='Raw Data'!B83 -> -9489.65 | C5: ='Raw Data'!C83 -> -11730.31 | D5: ='Raw Data'!D83 -> -29176.45 | E5: ='Raw Data'!E83 -> -14012.06 | F5: ='Raw Data'!F83 -> -9437.27 | G5: ='Raw Data'!G83 -> -10905.02 | H5: ='Raw Data'!H83 -> -18179.45 | I5: ='Raw Data'!I83 -> -14252.74 | ... K5: ='Raw Data'!K83 -> -14397.35
A6: Cash from Financing Activity | B6: ='Raw Data'!B84 -> -2579.36 | C6: ='Raw Data'!C84 -> 6639.94 | D6: ='Raw Data'!D84 -> -672.7 | E6: ='Raw Data'!E84 -> -1694.62 | F6: ='Raw Data'!F84 -> -37089.67 | G6: ='Raw Data'!G84 -> -23401.09 | H6: ='Raw Data'!H84 -> -6980.69 | I6: ='Raw Data'!I84 -> -11096.99 | ... K6: ='Raw Data'!K84 -> -21387.12
A7: Net Cash Flow | B7: ='Raw Data'!B85 -> -1244.65 | C7: ='Raw Data'!C85 -> 2933.02 | D7: ='Raw Data'!D85 -> -4513.2 | E7: ='Raw Data'!E85 -> 4462.04 | F7: ='Raw Data'!F85 -> -2200.26 | G7: ='Raw Data'!G85 -> 10074.88 | H7: ='Raw Data'!H85 -> -3477.06 | I7: ='Raw Data'!I85 -> -5049.06 | ... K7: ='Raw Data'!K85 -> -720.01

Sheet Customization
A1: How to use it?
A3: You can customize this workbook as you want.
B4: You can add custom formating, add conditional formating, add your own formulas… do ANYTHING.
B5: Please don't edit the "Data Sheet" only.
A7: After customization, you can upload this back on Screener.
B8: Upload on: | C8: https://www.screener.in/excel/
A10: Download your customized workbooks now onwards.
B11: Now whenever you will "Export to excel" from Screener, it will export your customized file.
A14: TESTING:
B15: This is a testing feature currently.
B16: You can report any formula errors on the worksheet at: support@screener.in

Sheet Raw Data
A1: COMPANY NAME | B1: TATA STEEL LTD | E1: =IF(B2<>B3, "A NEW VERSION OF THE WORKSHEET IS AVAILABLE", "")
A2: LATEST VERSION | B2: 2.1 | E2: PLEASE DO NOT MAKE ANY CHANGES TO THIS SHEET
A3: CURRENT VERSION | B3: 2.1
A5: META
A6: Number of shares | B6: =IF(B9>0, B9/B8, 0) -> 1247.918
A7: Face Value | B7: 1
A8: Current Price | B8: 175
A9: Market Capitalization | B9: 218385.65
A15: PROFIT & LOSS
A16: Report Date | B16: 42825 | C16: 43190 | D16: 43555 | E16: 43921 | F16: 44286 | G16: 44651 | H16: 45016 | I16: 45382 | J16: 45747 | K16: 46112
A17: Sales | B17: 112299.42 | C17: 123249.07 | D17: 157668.99 | E17: 139816.65 | F17: 156477.4 | G17: 243959.17 | H17: 243352.69 | I17: 229170.78 | J17: 218542.51 | K17: 232139.94
A18: Raw Material Cost | B18: 43843.03 | C18: 46137.01 | D18: 60877.05 | E18: 58039.99 | F18: 55100.81 | G18: 91076.61 | H18: 116597.19 | I18: 97506.39 | J18: 95097.3 | K18: 92628.07
A19: Change in Inventory | B19: 4538.13 | C19: -99.31 | D19: 96.71 | E19: 565.24 | F19: -1516.77 | G19: 7597.87 | H19: 3358.89 | I19: -4409.35 | J19: 96.65 | K19: -989.62
A20: Power and Fuel | B20: 5220.83 | C20: 4440.43 | D20: 5316.56 | E20: 5319.92 | F20: 5708.42 | G20: 8028.29 | H20: 9526.91 | I20: 16612.61 | J20: 13124.85 | K20: 14333.15
A21: Other Mfr. Exp | B21: 15799.14 | C21: 16955.79 | D21: 20734.28 | E21: 21232.69 | F21: 20744.93 | G21: 28834.06 | H21: 33144.83 | I21: 40116.91 | J21: 38700.5 | K21: 37485.96
A22: Employee Cost | B22: 17252.22 | C22: 17077.51 | D22: 18758.87 | E22: 18533.58 | F22: 19908.81 | G22: 23264.1 | H22: 22419.32 | I22: 24509.58 | J22: 24888.99 | K22: 25998.98
A23: Selling and admin | B23: 13772.32 | C23: 14423.87 | D23: 16917.14 | E23: 15599.07 | F23: 17509.77 | G23: 27445.67 | H23: 25519.92 | I23: 14453.57 | J23: 12137.26 | K23: 13348.99
A24: Other Expenses | B24: 7806.38 | C24: 2681.96 | D24: 5843.58 | E24: 4193.58 | F24: 5483.63 | G24: 9418.36 | H24: 7203.25 | I24: 9314.45 | J24: 9391.81 | K24: 13002.73
A25: Other Income | B25: -3789.11 | C25: 10898.41 | D25: 1524.31 | E25: -2883.63 | F25: 179.78 | G25: 1299.99 | H25: 1568.86 | I25: -6005.23 | J25: 876.7 | K25: 737.82
A26: Depreciation | B26: 5672.88 | C26: 5741.7 | D26: 7341.83 | E26: 8440.73 | F26: 9233.64 | G26: 9100.87 | H26: 9335.2 | I26: 9882.16 | J26: 10421.33 | K26: 11954.51
A27: Interest | B27: 5072.2 | C27: 5454.74 | D27: 7660.1 | E27: 7533.46 | F27: 7606.71 | G27: 5462.2 | H27: 6298.7 | I27: 7507.57 | J27: 7340.95 | K27: 7167.06
... A31: Dividend Amount | B31: 970.24 | C31: 1144.95 | D31: 1488.42 | E31: 1144.95 | F31: 2994.02 | G31: 6228.17 | H31: 4396.46 | I31: 4490.78 | J31: 4490.78 | K31: 4989.76
A40: Quarters
A41: Report Date | B41: 45382 | C41: 45473 | D41: 45565 | E41: 45657 | F41: 45747 | G41: 45838 | H41: 45930 | I41: 46022 | J41: 46112 | K41: 46203
A42: Sales | B42: 58687.31 | C42: 54771.39 | D42: 53904.71 | E42: 53648.3 | F42: 56218.11 | G42: 53178.12 | H42: 58689.29 | I42: 57002.4 | J42: 63270.13 | K42: 60794.29
A43: Expenses | B43: 52086.68 | C43: 48076.92 | D43: 47788.92 | E43: 47744.81 | F43: 49658.89 | G43: 45750.58 | H43: 49792.75 | I43: 48802.7 | J43: 53441.47 | K43: 51529.95
A44: Other Income | B44: -381.56 | C44: -5.51 | D44: 616.68 | E44: 141.82 | F44: 149.19 | G44: 236.27 | H44: -6.11 | I44: 465.17 | J44: 42.49 | K44: -16.65
A45: Depreciation | B45: 2567.95 | C45: 2535.43 | D45: 2596.74 | E45: 2569.19 | F45: 2719.97 | G45: 2744.3 | H45: 2893 | I45: 3048.81 | J45: 3268.4 | K45: 3639.65
A46: Interest | B46: 1842.25 | C46: 1776.71 | D46: 1971.4 | E46: 1804.09 | F46: 1788.75 | G46: 1852.43 | H46: 1774.96 | I46: 1747.29 | J46: 1792.38 | K46: 1770.51
A47: Profit before tax | B47: 1808.87 | C47: 2376.82 | D47: 2164.33 | E47: 1672.03 | F47: 2199.69 | G47: 3067.08 | H47: 4222.47 | I47: 3868.77 | J47: 4810.37 | K47: 3837.53
A48: Tax | B48: 1254.31 | C48: 1458.25 | D48: 1405.49 | E48: 1376.54 | F48: 998.81 | G48: 1059.72 | H48: 1039.38 | I48: 1138.4 | J48: 1845.37 | K48: 1452.29
A49: Net profit | B49: 611.48 | C49: 959.61 | D49: 833.45 | E49: 326.64 | F49: 1300.81 | G49: 2077.68 | H49: 3101.75 | I49: 2688.7 | J49: 2925.74 | K49: 2318.35
A50: Operating Profit | B50: 6600.63 | C50: 6694.47 | D50: 6115.79 | E50: 5903.49 | F50: 6559.22 | G50: 7427.54 | H50: 8896.54 | I50: 8199.7 | J50: 9828.66 | K50: 9264.34
A55: BALANCE SHEET
A56: Report Date | B56: 42825 | C56: 43190 | D56: 43555 | E56: 43921 | F56: 44286 | G56: 44651 | H56: 45016 | I56: 45382 | J56: 45747 | K56: 46112
A57: Equity Share Capital | B57: 970.24 | C57: 1144.95 | D57: 1144.94 | E57: 1144.95 | F57: 1197.61 | G57: 1221.21 | H57: 1221.24 | I57: 1247.44 | J57: 1247.44 | K57: 1247.44
A58: Reserves | B58: 36849.08 | C58: 59725.67 | D58: 67780.14 | E58: 72431.35 | F58: 73041.16 | G58: 113221.83 | H58: 101860.86 | I58: 90788.32 | J58: 89922.19 | K58: 100920.21
A59: Borrowings | B59: 83014.49 | C59: 92147.05 | D59: 100816.22 | E59: 116328.2 | F59: 88501.41 | G59: 75561.35 | H59: 84893.05 | I59: 87082.12 | J59: 94801.05 | K59: 92381.68
A60: Other Liabilities | B60: 51613.56 | C60: 55704.47 | D60: 63032.14 | E60: 59244.62 | F60: 81169.01 | G60: 92417.28 | H60: 97420.63 | I60: 90194.54 | J60: 89487.9 | K60: 101965.29
A61: Total | B61: 172447.37 | C61: 208722.14 | D61: 232773.44 | E61: 249149.12 | F61: 243909.19 | G61: 282421.67 | H61: 285395.78 | I61: 269312.42 | J61: 275458.58 | K61: 296514.62
...

Sheet Analysis
A1: Quarter | B1: Revenue | C1: Expenses | D1: Operating Profit | E1: Net Profit | F1: Operating Margin % | G1: Net Profit Margin % | H1: Expense Ratio % | I1: QoQ Revenue Growth % | J1: YoY Revenue Growth % | K1: Op. Margin Change
A2: 45382 | B2: 58687.31 | C2: 52086.68 | D2: =B2-C2 -> 6600.63 | E2: 611.48 | F2: =D2/B2 -> 0.11247116 | G2: =E2/B2 -> 0.010419288 | H2: =C2/B2 -> 0.88752884
A3: 45473 | B3: 54771.39 | C3: 48076.92 | D3: =B3-C3 -> 6694.47 | E3: 959.61 | F3: =D3/B3 -> 0.12222567 | G3: =E3/B3 -> 0.017520278 | H3: =C3/B3 -> 0.87777433 | I3: =(B3-B2)/B2 -> -0.066725157 | K3: =F3-F2 -> 0.0097545101
A4: 45565 | B4: 53904.71 | C4: 47788.92 | D4: =B4-C4 -> 6115.79 | E4: 833.45 | F4: =D4/B4 -> 0.11345558 | G4: =E4/B4 -> 0.015461543 | H4: =C4/B4 -> 0.88654442 | I4: =(B4-B3)/B3 -> -0.01582359 | K4: =F4-F3 -> -0.0087700955
A5: 45657 | B5: 53648.3 | C5: 47744.81 | D5: =B5-C5 -> 5903.49 | E5: 326.64 | F5: =D5/B5 -> 0.11004058 | G5: =E5/B5 -> 0.0060885433 | H5: =C5/B5 -> 0.88995942 | I5: =(B5-B4)/B4 -> -0.0047567272 | K5: =F5-F4 -> -0.0034149983
A6: 45747 | B6: 56218.11 | C6: 49658.89 | D6: =B6-C6 -> 6559.22 | E6: 1300.81 | F6: =D6/B6 -> 0.1166745 | G6: =E6/B6 -> 0.023138629 | H6: =C6/B6 -> 0.8833255 | I6: =(B6-B5)/B5 -> 0.047901052 | J6: =(B6-B2)/B2 -> -0.042073832 | K6: =F6-F5 -> 0.0066339231
A7: 45838 | B7: 53178.12 | C7: 45750.58 | D7: =B7-C7 -> 7427.54 | E7: 2077.68 | F7: =D7/B7 -> 0.13967286 | G7: =E7/B7 -> 0.039070204 | H7: =C7/B7 -> 0.86032714 | I7: =(B7-B6)/B6 -> -0.054074924 | J7: =(B7-B3)/B3 -> -0.029089457 | K7: =F7-F6 -> 0.022998356
A8: 45930 | B8: 58689.29 | C8: 49792.75 | D8: =B8-C8 -> 8896.54 | E8: 3101.75 | F8: =D8/B8 -> 0.15158711 | G8: =E8/B8 -> 0.052850358 | H8: =C8/B8 -> 0.84841289 | I8: =(B8-B7)/B7 -> 0.10363604 | J8: =(B8-B4)/B4 -> 0.088759962 | K8: =F8-F7 -> 0.011914254
A9: 46022 | B9: 57002.4 | C9: 48802.7 | D9: =B9-C9 -> 8199.7 | E9: 2688.7 | F9: =D9/B9 -> 0.14384833 | G9: =E9/B9 -> 0.047168189 | H9: =C9/B9 -> 0.85615167 | I9: =(B9-B8)/B8 -> -0.028742723 | J9: =(B9-B5)/B5 -> 0.062520154 | K9: =F9-F8 -> -0.0077387832
A10: 46112 | B10: 63270.13 | C10: 53441.47 | D10: =B10-C10 -> 9828.66 | E10: 2925.74 | F10: =D10/B10 -> 0.15534439 | G10: =E10/B10 -> 0.046242042 | H10: =C10/B10 -> 0.84465561 | I10: =(B10-B9)/B9 -> 0.10995555 | J10: =(B10-B6)/B6 -> 0.12544036 | K10: =F10-F9 -> 0.011496065
A11: 46203 | B11: 60794.29 | C11: 51529.95 | D11: =B11-C11 -> 9264.34 | E11: 2318.35 | F11: =D11/B11 -> 0.15238832 | G11: =E11/B11 -> 0.038134338 | H11: =C11/B11 -> 0.84761168 | I11: =(B11-B10)/B10 -> -0.039131261 | J11: =(B11-B7)/B7 -> 0.14321999 | K11: =F11-F10 -> -0.0029560693

Sheet Summary
A1: Highest operating margin | B1: =MAX(Analysis!F2:F100) -> 0.15534439
A2: Quarter of highest margin | B2: =TEXT(INDEX(Analysis!A2:A100,MATCH(MAX(Analysis!F2:F100),Analysis!F2:F100,0)),"mmm yyyy") -> Mar 2026
A3: Lowest operating margin | B3: =MIN(Analysis!F2:F100) -> 0.11004058
A4: Quarter of lowest margin | B4: =TEXT(INDEX(Analysis!A2:A100,MATCH(MIN(Analysis!F2:F100),Analysis!F2:F100,0)),"mmm yyyy") -> Dec 2024
A5: Average operating margin | B5: =AVERAGE(Analysis!F2:F100) -> 0.13177085
A6: Latest operating margin | B6: {=INDEX(Analysis!F2:F100,COUNT(Analysis!F2:F100))} -> 0.15238832
A7: Revenue growth, first to last quarter | B7: {=(INDEX(Analysis!B2:B100,COUNT(Analysis!B2:B100))-Analysis!B2)/Analysis!B2} -> 0.035901799
A8: Quarters where margin fell | B8: =COUNTIF(Analysis!K2:K100,"<0") -> 4
A9: Quarters compared | B9: =COUNT(Analysis!K2:K100) -> 9

Sheet Sorted_Filtered
A1: Quarter | B1: Revenue | C1: Expenses | D1: Operating Profit | E1: Net Profit | F1: Operating Margin % | G1: Net Profit Margin % | H1: Expense Ratio % | I1: QoQ Revenue Growth % | J1: YoY Revenue Growth % | K1: Op. Margin Change
A2: 46112 | B2: 63270.13 | C2: 53441.47 | D2: 9828.66 | E2: 2925.74 | F2: 0.15534439 | G2: 0.046242042 | H2: 0.84465561 | I2: 0.10995555 | J2: 0.12544036 | K2: 0.011496065
A3: 46203 | B3: 60794.29 | C3: 51529.95 | D3: 9264.34 | E3: 2318.35 | F3: 0.15238832 | G3: 0.038134338 | H3: 0.84761168 | I3: -0.039131261 | J3: 0.14321999 | K3: -0.0029560693
A4: 45930 | B4: 58689.29 | C4: 49792.75 | D4: 8896.54 | E4: 3101.75 | F4: 0.15158711 | G4: 0.052850358 | H4: 0.84841289 | I4: 0.10363604 | J4: 0.088759962 | K4: 0.011914254
A5: 46022 | B5: 57002.4 | C5: 48802.7 | D5: 8199.7 | E5: 2688.7 | F5: 0.14384833 | G5: 0.047168189 | H5: 0.85615167 | I5: -0.028742723 | J5: 0.062520154 | K5: -0.0077387832
A6: 45838 | B6: 53178.12 | C6: 45750.58 | D6: 7427.54 | E6: 2077.68 | F6: 0.13967286 | G6: 0.039070204 | H6: 0.86032714 | I6: -0.054074924 | J6: -0.029089457 | K6: 0.022998356
A7: 45473 | B7: 54771.39 | C7: 48076.92 | D7: 6694.47 | E7: 959.61 | F7: 0.12222567 | G7: 0.017520278 | H7: 0.87777433 | I7: -0.066725157 | K7: 0.0097545101
A8: 45747 | B8: 56218.11 | C8: 49658.89 | D8: 6559.22 | E8: 1300.81 | F8: 0.1166745 | G8: 0.023138629 | H8: 0.8833255 | I8: 0.047901052 | J8: -0.042073832 | K8: 0.0066339231
A9: 45565 | B9: 53904.71 | C9: 47788.92 | D9: 6115.79 | E9: 833.45 | F9: 0.11345558 | G9: 0.015461543 | H9: 0.88654442 | I9: -0.01582359 | K9: -0.0087700955
A10: 45382 | B10: 58687.31 | C10: 52086.68 | D10: 6600.63 | E10: 611.48 | F10: 0.11247116 | G10: 0.010419288 | H10: 0.88752884
A11: 45657 | B11: 53648.3 | C11: 47744.81 | D11: 5903.49 | E11: 326.64 | F11: 0.11004058 | G11: 0.0060885433 | H11: 0.88995942 | I11: -0.0047567272 | K11: -0.0034149983
